[2024-05-25T18:22:11.823+0000] {local_task_job_runner.py:120} INFO - ::group::Pre task execution logs
[2024-05-25T18:22:11.870+0000] {taskinstance.py:2076} INFO - Dependencies all met for dep_context=non-requeueable deps ti=<TaskInstance: welcome_dag.get_and_save_data manual__2024-05-25T18:22:02.975284+00:00 [queued]>
[2024-05-25T18:22:11.897+0000] {taskinstance.py:2076} INFO - Dependencies all met for dep_context=requeueable deps ti=<TaskInstance: welcome_dag.get_and_save_data manual__2024-05-25T18:22:02.975284+00:00 [queued]>
[2024-05-25T18:22:11.898+0000] {taskinstance.py:2306} INFO - Starting attempt 1 of 1
[2024-05-25T18:22:11.946+0000] {taskinstance.py:2330} INFO - Executing <Task(PythonOperator): get_and_save_data> on 2024-05-25 18:22:02.975284+00:00
[2024-05-25T18:22:11.952+0000] {standard_task_runner.py:63} INFO - Started process 63 to run task
[2024-05-25T18:22:11.958+0000] {standard_task_runner.py:90} INFO - Running: ['airflow', 'tasks', 'run', 'welcome_dag', 'get_and_save_data', 'manual__2024-05-25T18:22:02.975284+00:00', '--job-id', '28', '--raw', '--subdir', 'DAGS_FOLDER/welcome_dag.py', '--cfg-path', '/tmp/tmp214845uh']
[2024-05-25T18:22:11.990+0000] {standard_task_runner.py:91} INFO - Job 28: Subtask get_and_save_data
[2024-05-25T18:22:12.143+0000] {task_command.py:426} INFO - Running <TaskInstance: welcome_dag.get_and_save_data manual__2024-05-25T18:22:02.975284+00:00 [running]> on host 689c7f9d3625
[2024-05-25T18:22:12.329+0000] {taskinstance.py:2648} INFO - Exporting env vars: AIRFLOW_CTX_DAG_OWNER='airflow' AIRFLOW_CTX_DAG_ID='welcome_dag' AIRFLOW_CTX_TASK_ID='get_and_save_data' AIRFLOW_CTX_EXECUTION_DATE='2024-05-25T18:22:02.975284+00:00' AIRFLOW_CTX_TRY_NUMBER='1' AIRFLOW_CTX_DAG_RUN_ID='manual__2024-05-25T18:22:02.975284+00:00'
[2024-05-25T18:22:12.331+0000] {taskinstance.py:430} INFO - ::endgroup::
[2024-05-25T18:23:20.157+0000] {taskinstance.py:441} INFO - ::group::Post task execution logs
[2024-05-25T18:23:20.158+0000] {taskinstance.py:2905} ERROR - Task failed with exception
Traceback (most recent call last):
  File "/home/airflow/.local/lib/python3.12/site-packages/airflow/models/taskinstance.py", line 465, in _execute_task
    result = _execute_callable(context=context, **execute_callable_kwargs)
             ^^^^^^^^^^^^^^^^^^^^^^^^^^^^^^^^^^^^^^^^^^^^^^^^^^^^^^^^^^^^^
  File "/home/airflow/.local/lib/python3.12/site-packages/airflow/models/taskinstance.py", line 432, in _execute_callable
    return execute_callable(context=context, **execute_callable_kwargs)
           ^^^^^^^^^^^^^^^^^^^^^^^^^^^^^^^^^^^^^^^^^^^^^^^^^^^^^^^^^^^^
  File "/home/airflow/.local/lib/python3.12/site-packages/airflow/models/baseoperator.py", line 400, in wrapper
    return func(self, *args, **kwargs)
           ^^^^^^^^^^^^^^^^^^^^^^^^^^^
  File "/home/airflow/.local/lib/python3.12/site-packages/airflow/operators/python.py", line 235, in execute
    return_value = self.execute_callable()
                   ^^^^^^^^^^^^^^^^^^^^^^^
  File "/home/airflow/.local/lib/python3.12/site-packages/airflow/operators/python.py", line 252, in execute_callable
    return self.python_callable(*self.op_args, **self.op_kwargs)
           ^^^^^^^^^^^^^^^^^^^^^^^^^^^^^^^^^^^^^^^^^^^^^^^^^^^^^
  File "/opt/airflow/dags/welcome_dag.py", line 20, in get_and_save_data
    driver = webdriver.Firefox()
             ^^^^^^^^^^^^^^^^^^^
  File "/home/airflow/.local/lib/python3.12/site-packages/selenium/webdriver/firefox/webdriver.py", line 71, in __init__
    super().__init__(command_executor=executor, options=options)
  File "/home/airflow/.local/lib/python3.12/site-packages/selenium/webdriver/remote/webdriver.py", line 208, in __init__
    self.start_session(capabilities)
  File "/home/airflow/.local/lib/python3.12/site-packages/selenium/webdriver/remote/webdriver.py", line 292, in start_session
    response = self.execute(Command.NEW_SESSION, caps)["value"]
               ^^^^^^^^^^^^^^^^^^^^^^^^^^^^^^^^^^^^^^^
  File "/home/airflow/.local/lib/python3.12/site-packages/selenium/webdriver/remote/webdriver.py", line 347, in execute
    self.error_handler.check_response(response)
  File "/home/airflow/.local/lib/python3.12/site-packages/selenium/webdriver/remote/errorhandler.py", line 229, in check_response
    raise exception_class(message, screen, stacktrace)
selenium.common.exceptions.WebDriverException: Message: Process unexpectedly closed with status 255

[2024-05-25T18:23:20.184+0000] {taskinstance.py:1206} INFO - Marking task as FAILED. dag_id=welcome_dag, task_id=get_and_save_data, run_id=manual__2024-05-25T18:22:02.975284+00:00, execution_date=20240525T182202, start_date=20240525T182211, end_date=20240525T182320
[2024-05-25T18:23:20.227+0000] {standard_task_runner.py:110} ERROR - Failed to execute job 28 for task get_and_save_data (Message: Process unexpectedly closed with status 255
; 63)
[2024-05-25T18:23:20.274+0000] {local_task_job_runner.py:240} INFO - Task exited with return code 1
[2024-05-25T18:23:20.304+0000] {taskinstance.py:3498} INFO - 0 downstream tasks scheduled from follow-on schedule check
[2024-05-25T18:23:20.308+0000] {local_task_job_runner.py:222} INFO - ::endgroup::
